'use client';

import React from 'react';
import { AlertTriangle, RefreshCw } from 'lucide-react';
import { Button } from './ui/button';

interface ErrorBoundaryState {
  hasError: boolean;
  error?: Error;
}

interface ErrorBoundaryProps {
  children: React.ReactNode;
  fallback?: React.ComponentType<{ error?: Error; retry: () => void }>;
}

class ErrorBoundary extends React.Component<ErrorBoundaryProps, ErrorBoundaryState> {
  constructor(props: ErrorBoundaryProps) {
    super(props);
    this.state = { hasError: false };
  }

  static getDerivedStateFromError(error: Error): ErrorBoundaryState {
    return { hasError: true, error };
  }

  componentDidCatch(error: Error, errorInfo: React.ErrorInfo) {
    console.error('Error caught by boundary:', error, errorInfo);
  }

  retry = () => {
    this.setState({ hasError: false, error: undefined });
  };

  render() {
    if (this.state.hasError) {
      if (this.props.fallback) {
        const FallbackComponent = this.props.fallback;
        return <FallbackComponent error={this.state.error} retry={this.retry} />;
      }

      return <DefaultErrorFallback error={this.state.error} retry={this.retry} />;
    }

    return this.props.children;
  }
}

function DefaultErrorFallback({ error, retry }: { error?: Error; retry: () => void }) {
  return (
    <div className="flex flex-col items-center justify-center min-h-[200px] p-6 text-center">
      <AlertTriangle className="h-12 w-12 text-red-500 mb-4" />
      <h3 className="text-lg font-semibold text-gray-900 mb-2">Something went wrong</h3>
      <p className="text-gray-600 mb-4 max-w-md">
        {error?.message || 'An unexpected error occurred. Please try again.'}
      </p>
      <Button onClick={retry} className="flex items-center gap-2">
        <RefreshCw className="h-4 w-4" />
        Try Again
      </Button>
    </div>
  );
}

// Hook for functional components to handle async errors
export function useErrorHandler() {
  const [error, setError] = React.useState<Error | null>(null);

  const handleError = React.useCallback((error: Error) => {
    console.error('Async error:', error);
    setError(error);
  }, []);

  const clearError = React.useCallback(() => {
    setError(null);
  }, []);

  if (error) {
    throw error; // This will be caught by the nearest ErrorBoundary
  }

  return { handleError, clearError };
}

export default ErrorBoundary; 